2017-12-27 13:56:08,583 [Thread-3:140209787668224] [django.request:256] [base:handle_uncaught_exception] [ERROR]- Internal Server Error: /user/login_handle/
Traceback (most recent call last):
  File "/root/.virtualenvs/cms/lib/python3.5/site-packages/django/core/handlers/base.py", line 132, in get_response
    response = wrapped_callback(request, *callback_args, **callback_kwargs)
  File "/root/cms/cms/user/views.py", line 107, in login_handle
    response_data = result['errorData']
KeyError: 'errorData'
2017-12-27 13:58:28,317 [Thread-3:140029168162560] [django.request:256] [base:handle_uncaught_exception] [ERROR]- Internal Server Error: /user/login_handle/
Traceback (most recent call last):
  File "/root/.virtualenvs/cms/lib/python3.5/site-packages/django/core/handlers/base.py", line 132, in get_response
    response = wrapped_callback(request, *callback_args, **callback_kwargs)
  File "/root/cms/cms/user/views.py", line 107, in login_handle
    response_data = result['errorData']
KeyError: 'errorData'
