2017-12-27 13:56:08,583 [Thread-3:140209787668224] [django.request:256] [base:handle_uncaught_exception] [ERROR]- Internal Server Error: /user/login_handle/
Traceback (most recent call last):
  File "/root/.virtualenvs/cms/lib/python3.5/site-packages/django/core/handlers/base.py", line 132, in get_response
    response = wrapped_callback(request, *callback_args, **callback_kwargs)
  File "/root/cms/cms/user/views.py", line 107, in login_handle
    response_data = result['errorData']
KeyError: 'errorData'
2017-12-27 13:58:28,317 [Thread-3:140029168162560] [django.request:256] [base:handle_uncaught_exception] [ERROR]- Internal Server Error: /user/login_handle/
Traceback (most recent call last):
  File "/root/.virtualenvs/cms/lib/python3.5/site-packages/django/core/handlers/base.py", line 132, in get_response
    response = wrapped_callback(request, *callback_args, **callback_kwargs)
  File "/root/cms/cms/user/views.py", line 107, in login_handle
    response_data = result['errorData']
KeyError: 'errorData'
2018-01-23 09:58:28,888 [Thread-7:139938543003392] [django.request:170] [base:get_response] [WARNING]- Not Found: /favicon.ico
2018-01-23 10:18:20,381 [Thread-1:140082753279744] [django.request:256] [base:handle_uncaught_exception] [ERROR]- Internal Server Error: /user/logout/
Traceback (most recent call last):
  File "/root/.virtualenvs/cms/lib/python3.5/site-packages/django/core/handlers/base.py", line 132, in get_response
    response = wrapped_callback(request, *callback_args, **callback_kwargs)
  File "/root/cms/cms/decorate.py", line 42, in inner
    return func(request, *args, **kwargs)
  File "/root/cms/cms/user/views.py", line 159, in logout
    userid, presend_cookie = cookie_handler.get_cookie(request)
  File "/root/cms/cms/cookie_handler.py", line 18, in get_cookie
    presend_cookie = settings.__getattr__(cookies_variable_name)
  File "/root/.virtualenvs/cms/lib/python3.5/site-packages/django/conf/__init__.py", line 49, in __getattr__
    return getattr(self._wrapped, name)
AttributeError: 'Settings' object has no attribute 'cookies_15'
2018-01-23 10:20:08,040 [Thread-1:140657888225024] [django.request:256] [base:handle_uncaught_exception] [ERROR]- Internal Server Error: /user/logout/
Traceback (most recent call last):
  File "/root/.virtualenvs/cms/lib/python3.5/site-packages/django/core/handlers/base.py", line 132, in get_response
    response = wrapped_callback(request, *callback_args, **callback_kwargs)
  File "/root/cms/cms/decorate.py", line 42, in inner
    return func(request, *args, **kwargs)
  File "/root/cms/cms/user/views.py", line 159, in logout
    userid, presend_cookie = cookie_handler.get_cookie(request)
  File "/root/cms/cms/cookie_handler.py", line 18, in get_cookie
    presend_cookie = settings.__getattr__(cookies_variable_name)
  File "/root/.virtualenvs/cms/lib/python3.5/site-packages/django/conf/__init__.py", line 49, in __getattr__
    return getattr(self._wrapped, name)
AttributeError: 'Settings' object has no attribute 'cookies_15'
2018-01-23 10:29:28,769 [Thread-26:140576150251264] [django.request:256] [base:handle_uncaught_exception] [ERROR]- Internal Server Error: /user/listUser/
Traceback (most recent call last):
  File "/root/.virtualenvs/cms/lib/python3.5/site-packages/django/core/handlers/base.py", line 132, in get_response
    response = wrapped_callback(request, *callback_args, **callback_kwargs)
  File "/root/cms/cms/decorate.py", line 21, in inner
    permissions = settings.__getattr__(variable_name)
  File "/root/.virtualenvs/cms/lib/python3.5/site-packages/django/conf/__init__.py", line 49, in __getattr__
    return getattr(self._wrapped, name)
AttributeError: 'Settings' object has no attribute 'permissions_15'
2018-01-23 10:29:29,989 [Thread-27:140576150251264] [django.request:256] [base:handle_uncaught_exception] [ERROR]- Internal Server Error: /user/logout/
Traceback (most recent call last):
  File "/root/.virtualenvs/cms/lib/python3.5/site-packages/django/core/handlers/base.py", line 132, in get_response
    response = wrapped_callback(request, *callback_args, **callback_kwargs)
  File "/root/cms/cms/decorate.py", line 42, in inner
    return func(request, *args, **kwargs)
  File "/root/cms/cms/user/views.py", line 159, in logout
    userid, presend_cookie = cookie_handler.get_cookie(request)
  File "/root/cms/cms/cookie_handler.py", line 18, in get_cookie
    presend_cookie = settings.__getattr__(cookies_variable_name)
  File "/root/.virtualenvs/cms/lib/python3.5/site-packages/django/conf/__init__.py", line 49, in __getattr__
    return getattr(self._wrapped, name)
AttributeError: 'Settings' object has no attribute 'cookies_15'
2018-01-23 10:29:41,158 [Thread-34:140576150251264] [django.request:256] [base:handle_uncaught_exception] [ERROR]- Internal Server Error: /user/GetUserPermiss/15
Traceback (most recent call last):
  File "/root/.virtualenvs/cms/lib/python3.5/site-packages/django/core/handlers/base.py", line 151, in get_response
    % (callback.__module__, view_name))
ValueError: The view decorate.inner didn't return an HttpResponse object. It returned None instead.
2018-01-23 10:30:27,014 [Thread-72:140576141858560] [django.request:256] [base:handle_uncaught_exception] [ERROR]- Internal Server Error: /user/GetUserPermiss/15
Traceback (most recent call last):
  File "/root/.virtualenvs/cms/lib/python3.5/site-packages/django/core/handlers/base.py", line 151, in get_response
    % (callback.__module__, view_name))
ValueError: The view decorate.inner didn't return an HttpResponse object. It returned None instead.
2018-01-23 10:31:16,818 [Thread-122:140576141858560] [django.request:256] [base:handle_uncaught_exception] [ERROR]- Internal Server Error: /user/GetUserPermiss/15
Traceback (most recent call last):
  File "/root/.virtualenvs/cms/lib/python3.5/site-packages/django/core/handlers/base.py", line 151, in get_response
    % (callback.__module__, view_name))
ValueError: The view decorate.inner didn't return an HttpResponse object. It returned None instead.
2018-01-23 10:31:31,976 [Thread-171:140576124811008] [django.request:256] [base:handle_uncaught_exception] [ERROR]- Internal Server Error: /user/GetUserPermiss/15
Traceback (most recent call last):
  File "/root/.virtualenvs/cms/lib/python3.5/site-packages/django/core/handlers/base.py", line 151, in get_response
    % (callback.__module__, view_name))
ValueError: The view decorate.inner didn't return an HttpResponse object. It returned None instead.
2018-01-23 10:32:38,568 [Thread-25:140406169720576] [django.request:256] [base:handle_uncaught_exception] [ERROR]- Internal Server Error: /user/logout/
Traceback (most recent call last):
  File "/root/.virtualenvs/cms/lib/python3.5/site-packages/django/core/handlers/base.py", line 132, in get_response
    response = wrapped_callback(request, *callback_args, **callback_kwargs)
  File "/root/cms/cms/decorate.py", line 42, in inner
    return func(request, *args, **kwargs)
  File "/root/cms/cms/user/views.py", line 159, in logout
    userid, presend_cookie = cookie_handler.get_cookie(request)
  File "/root/cms/cms/cookie_handler.py", line 18, in get_cookie
    presend_cookie = settings.__getattr__(cookies_variable_name)
  File "/root/.virtualenvs/cms/lib/python3.5/site-packages/django/conf/__init__.py", line 49, in __getattr__
    return getattr(self._wrapped, name)
AttributeError: 'Settings' object has no attribute 'cookies_15'
2018-01-23 10:32:41,670 [Thread-26:140406169720576] [django.request:170] [base:get_response] [WARNING]- Not Found: /user/LOGIN/
2018-01-23 10:59:00,731 [Thread-171:140406157567744] [django.request:256] [base:handle_uncaught_exception] [ERROR]- Internal Server Error: /user/getUserInfo/
Traceback (most recent call last):
  File "/root/.virtualenvs/cms/lib/python3.5/site-packages/django/core/handlers/base.py", line 132, in get_response
    response = wrapped_callback(request, *callback_args, **callback_kwargs)
  File "/root/cms/cms/decorate.py", line 42, in inner
    return func(request, *args, **kwargs)
  File "/root/cms/cms/user/views.py", line 200, in getUserInfo
    user_count = len(user_infos)
TypeError: object of type 'NoneType' has no len()
2018-01-23 14:10:06,595 [Thread-1:140064335243008] [django.request:256] [base:handle_uncaught_exception] [ERROR]- Internal Server Error: /user/GetUserPermiss/15
Traceback (most recent call last):
  File "/root/.virtualenvs/cms/lib/python3.5/site-packages/django/core/handlers/base.py", line 132, in get_response
    response = wrapped_callback(request, *callback_args, **callback_kwargs)
  File "/root/cms/cms/decorate.py", line 42, in inner
    return func(request, *args, **kwargs)
  File "/root/cms/cms/user/views.py", line 240, in GetUserPermiss
    userid, presend_cookie = cookie_handler.get_cookie(request)
  File "/root/cms/cms/cookie_handler.py", line 18, in get_cookie
    presend_cookie = settings.__getattr__(cookies_variable_name)
  File "/root/.virtualenvs/cms/lib/python3.5/site-packages/django/conf/__init__.py", line 49, in __getattr__
    return getattr(self._wrapped, name)
AttributeError: 'Settings' object has no attribute 'cookies_15'
2018-01-23 14:10:08,409 [Thread-3:140064335243008] [django.request:256] [base:handle_uncaught_exception] [ERROR]- Internal Server Error: /user/permissions/
Traceback (most recent call last):
  File "/root/.virtualenvs/cms/lib/python3.5/site-packages/django/core/handlers/base.py", line 132, in get_response
    response = wrapped_callback(request, *callback_args, **callback_kwargs)
  File "/root/cms/cms/decorate.py", line 42, in inner
    return func(request, *args, **kwargs)
  File "/root/cms/cms/decorate.py", line 21, in inner
    permissions = settings.__getattr__(variable_name)
  File "/root/.virtualenvs/cms/lib/python3.5/site-packages/django/conf/__init__.py", line 49, in __getattr__
    return getattr(self._wrapped, name)
AttributeError: 'Settings' object has no attribute 'permissions_15'
2018-01-23 14:10:47,900 [Thread-28:140064335243008] [django.request:256] [base:handle_uncaught_exception] [ERROR]- Internal Server Error: /user/listUser/
Traceback (most recent call last):
  File "/root/.virtualenvs/cms/lib/python3.5/site-packages/django/core/handlers/base.py", line 132, in get_response
    response = wrapped_callback(request, *callback_args, **callback_kwargs)
  File "/root/cms/cms/decorate.py", line 21, in inner
    permissions = settings.__getattr__(variable_name)
  File "/root/.virtualenvs/cms/lib/python3.5/site-packages/django/conf/__init__.py", line 49, in __getattr__
    return getattr(self._wrapped, name)
AttributeError: 'Settings' object has no attribute 'permissions_15'
2018-01-23 14:10:56,685 [Thread-29:140064335243008] [django.request:256] [base:handle_uncaught_exception] [ERROR]- Internal Server Error: /user/logout/
Traceback (most recent call last):
  File "/root/.virtualenvs/cms/lib/python3.5/site-packages/django/core/handlers/base.py", line 132, in get_response
    response = wrapped_callback(request, *callback_args, **callback_kwargs)
  File "/root/cms/cms/decorate.py", line 42, in inner
    return func(request, *args, **kwargs)
  File "/root/cms/cms/user/views.py", line 159, in logout
    userid, presend_cookie = cookie_handler.get_cookie(request)
  File "/root/cms/cms/cookie_handler.py", line 18, in get_cookie
    presend_cookie = settings.__getattr__(cookies_variable_name)
  File "/root/.virtualenvs/cms/lib/python3.5/site-packages/django/conf/__init__.py", line 49, in __getattr__
    return getattr(self._wrapped, name)
AttributeError: 'Settings' object has no attribute 'cookies_15'
2018-01-23 14:37:01,256 [Thread-31:140682073143040] [django.request:256] [base:handle_uncaught_exception] [ERROR]- Internal Server Error: /user/getUserInfo/
Traceback (most recent call last):
  File "/root/.virtualenvs/cms/lib/python3.5/site-packages/django/core/handlers/base.py", line 132, in get_response
    response = wrapped_callback(request, *callback_args, **callback_kwargs)
  File "/root/cms/cms/decorate.py", line 42, in inner
    return func(request, *args, **kwargs)
  File "/root/cms/cms/user/views.py", line 196, in getUserInfo
    if "appendData" in result.keys():
AttributeError: 'str' object has no attribute 'keys'
2018-01-23 14:38:04,632 [Thread-8:139960489408256] [django.request:256] [base:handle_uncaught_exception] [ERROR]- Internal Server Error: /user/getUserInfo/
Traceback (most recent call last):
  File "/root/.virtualenvs/cms/lib/python3.5/site-packages/django/core/handlers/base.py", line 132, in get_response
    response = wrapped_callback(request, *callback_args, **callback_kwargs)
  File "/root/cms/cms/decorate.py", line 42, in inner
    return func(request, *args, **kwargs)
  File "/root/cms/cms/user/views.py", line 196, in getUserInfo
    if "appendData" in result.keys():
AttributeError: 'str' object has no attribute 'keys'
2018-01-23 14:45:44,952 [Thread-9:140700902065920] [django.request:256] [base:handle_uncaught_exception] [ERROR]- Internal Server Error: /user/GetUserPermiss/15
Traceback (most recent call last):
  File "/root/.virtualenvs/cms/lib/python3.5/site-packages/django/core/handlers/base.py", line 132, in get_response
    response = wrapped_callback(request, *callback_args, **callback_kwargs)
  File "/root/cms/cms/decorate.py", line 42, in inner
    return func(request, *args, **kwargs)
  File "/root/cms/cms/user/views.py", line 256, in GetUserPermiss
    permissions.append(result[i]['permissName'])
KeyError: 0
2018-01-23 14:46:06,249 [Thread-26:139778972448512] [django.request:256] [base:handle_uncaught_exception] [ERROR]- Internal Server Error: /user/listUser/
Traceback (most recent call last):
  File "/root/.virtualenvs/cms/lib/python3.5/site-packages/django/core/handlers/base.py", line 132, in get_response
    response = wrapped_callback(request, *callback_args, **callback_kwargs)
  File "/root/cms/cms/decorate.py", line 21, in inner
    permissions = settings.__getattr__(variable_name)
  File "/root/.virtualenvs/cms/lib/python3.5/site-packages/django/conf/__init__.py", line 49, in __getattr__
    return getattr(self._wrapped, name)
AttributeError: 'Settings' object has no attribute 'permissions_15'
2018-01-23 14:46:14,974 [Thread-34:139778972448512] [django.request:256] [base:handle_uncaught_exception] [ERROR]- Internal Server Error: /user/GetUserPermiss/15
Traceback (most recent call last):
  File "/root/.virtualenvs/cms/lib/python3.5/site-packages/django/core/handlers/base.py", line 132, in get_response
    response = wrapped_callback(request, *callback_args, **callback_kwargs)
  File "/root/cms/cms/decorate.py", line 42, in inner
    return func(request, *args, **kwargs)
  File "/root/cms/cms/user/views.py", line 256, in GetUserPermiss
    permissions.append(result[i]['permissName'])
KeyError: 0
2018-01-23 14:47:08,002 [Thread-26:140360963634944] [django.request:256] [base:handle_uncaught_exception] [ERROR]- Internal Server Error: /user/listUser/
Traceback (most recent call last):
  File "/root/.virtualenvs/cms/lib/python3.5/site-packages/django/core/handlers/base.py", line 132, in get_response
    response = wrapped_callback(request, *callback_args, **callback_kwargs)
  File "/root/cms/cms/decorate.py", line 21, in inner
    permissions = settings.__getattr__(variable_name)
  File "/root/.virtualenvs/cms/lib/python3.5/site-packages/django/conf/__init__.py", line 49, in __getattr__
    return getattr(self._wrapped, name)
AttributeError: 'Settings' object has no attribute 'permissions_15'
2018-01-23 14:47:21,766 [Thread-34:140360963634944] [django.request:256] [base:handle_uncaught_exception] [ERROR]- Internal Server Error: /user/GetUserPermiss/15
Traceback (most recent call last):
  File "/root/.virtualenvs/cms/lib/python3.5/site-packages/django/core/handlers/base.py", line 132, in get_response
    response = wrapped_callback(request, *callback_args, **callback_kwargs)
  File "/root/cms/cms/decorate.py", line 42, in inner
    return func(request, *args, **kwargs)
  File "/root/cms/cms/user/views.py", line 256, in GetUserPermiss
    permissions.append(result[i]['permissName'])
KeyError: 0
2018-01-23 14:49:25,454 [Thread-32:140512740767488] [django.request:256] [base:handle_uncaught_exception] [ERROR]- Internal Server Error: /user/GetUserPermiss/15
Traceback (most recent call last):
  File "/root/.virtualenvs/cms/lib/python3.5/site-packages/django/core/handlers/base.py", line 132, in get_response
    response = wrapped_callback(request, *callback_args, **callback_kwargs)
  File "/root/cms/cms/decorate.py", line 42, in inner
    return func(request, *args, **kwargs)
  File "/root/cms/cms/user/views.py", line 257, in GetUserPermiss
    permissions.append(result[i]['permissName'])
KeyError: 0
2018-01-23 16:23:23,942 [Thread-1:139644343969536] [django.request:256] [base:handle_uncaught_exception] [ERROR]- Internal Server Error: /user/permissions/
Traceback (most recent call last):
  File "/root/.virtualenvs/cms/lib/python3.5/site-packages/django/core/urlresolvers.py", line 394, in urlconf_module
    return self._urlconf_module
AttributeError: 'RegexURLResolver' object has no attribute '_urlconf_module'

During handling of the above exception, another exception occurred:

Traceback (most recent call last):
  File "/root/.virtualenvs/cms/lib/python3.5/site-packages/django/core/handlers/base.py", line 119, in get_response
    resolver_match = resolver.resolve(request.path_info)
  File "/root/.virtualenvs/cms/lib/python3.5/site-packages/django/core/urlresolvers.py", line 366, in resolve
    for pattern in self.url_patterns:
  File "/root/.virtualenvs/cms/lib/python3.5/site-packages/django/core/urlresolvers.py", line 402, in url_patterns
    patterns = getattr(self.urlconf_module, "urlpatterns", self.urlconf_module)
  File "/root/.virtualenvs/cms/lib/python3.5/site-packages/django/core/urlresolvers.py", line 396, in urlconf_module
    self._urlconf_module = import_module(self.urlconf_name)
  File "/root/.virtualenvs/cms/lib/python3.5/importlib/__init__.py", line 126, in import_module
    return _bootstrap._gcd_import(name[level:], package, level)
  File "<frozen importlib._bootstrap>", line 986, in _gcd_import
  File "<frozen importlib._bootstrap>", line 969, in _find_and_load
  File "<frozen importlib._bootstrap>", line 958, in _find_and_load_unlocked
  File "<frozen importlib._bootstrap>", line 673, in _load_unlocked
  File "<frozen importlib._bootstrap_external>", line 665, in exec_module
  File "<frozen importlib._bootstrap>", line 222, in _call_with_frames_removed
  File "/root/cms/cms/cms/urls.py", line 22, in <module>
    url(r'^user/', include('user.urls', namespace='user')),
  File "/root/.virtualenvs/cms/lib/python3.5/site-packages/django/conf/urls/__init__.py", line 33, in include
    urlconf_module = import_module(urlconf_module)
  File "/root/.virtualenvs/cms/lib/python3.5/importlib/__init__.py", line 126, in import_module
    return _bootstrap._gcd_import(name[level:], package, level)
  File "<frozen importlib._bootstrap>", line 986, in _gcd_import
  File "<frozen importlib._bootstrap>", line 969, in _find_and_load
  File "<frozen importlib._bootstrap>", line 958, in _find_and_load_unlocked
  File "<frozen importlib._bootstrap>", line 673, in _load_unlocked
  File "<frozen importlib._bootstrap_external>", line 665, in exec_module
  File "<frozen importlib._bootstrap>", line 222, in _call_with_frames_removed
  File "/root/cms/cms/user/urls.py", line 41, in <module>
    url(r'^GetUserPermiss/(\d*)$', views.GetUserPermiss, name='GetUserPermiss'),
AttributeError: module 'user.views' has no attribute 'GetUserPermiss'
2018-01-23 16:25:29,712 [Thread-3:139644343969536] [django.request:256] [base:handle_uncaught_exception] [ERROR]- Internal Server Error: /user/permissions/
Traceback (most recent call last):
  File "/root/.virtualenvs/cms/lib/python3.5/site-packages/django/core/handlers/base.py", line 132, in get_response
    response = wrapped_callback(request, *callback_args, **callback_kwargs)
  File "/root/cms/cms/decorate.py", line 42, in inner
    return func(request, *args, **kwargs)
  File "/root/cms/cms/decorate.py", line 21, in inner
    permissions = settings.__getattr__(variable_name)
  File "/root/.virtualenvs/cms/lib/python3.5/site-packages/django/conf/__init__.py", line 49, in __getattr__
    return getattr(self._wrapped, name)
AttributeError: 'Settings' object has no attribute 'permissions_15'
2018-01-23 16:25:37,826 [Thread-11:139644343969536] [django.request:170] [base:get_response] [WARNING]- Not Found: /user/permissions/15
2018-01-23 16:25:56,820 [Thread-1:140390565701376] [django.request:256] [base:handle_uncaught_exception] [ERROR]- Internal Server Error: /user/permissions/
Traceback (most recent call last):
  File "/root/.virtualenvs/cms/lib/python3.5/site-packages/django/core/handlers/base.py", line 132, in get_response
    response = wrapped_callback(request, *callback_args, **callback_kwargs)
  File "/root/cms/cms/decorate.py", line 42, in inner
    return func(request, *args, **kwargs)
  File "/root/cms/cms/decorate.py", line 21, in inner
    permissions = settings.__getattr__(variable_name)
  File "/root/.virtualenvs/cms/lib/python3.5/site-packages/django/conf/__init__.py", line 49, in __getattr__
    return getattr(self._wrapped, name)
AttributeError: 'Settings' object has no attribute 'permissions_15'
2018-01-23 16:26:00,317 [Thread-27:140390334199552] [django.request:256] [base:handle_uncaught_exception] [ERROR]- Internal Server Error: /user/listUser/
Traceback (most recent call last):
  File "/root/.virtualenvs/cms/lib/python3.5/site-packages/django/core/handlers/base.py", line 132, in get_response
    response = wrapped_callback(request, *callback_args, **callback_kwargs)
  File "/root/cms/cms/decorate.py", line 21, in inner
    permissions = settings.__getattr__(variable_name)
  File "/root/.virtualenvs/cms/lib/python3.5/site-packages/django/conf/__init__.py", line 49, in __getattr__
    return getattr(self._wrapped, name)
AttributeError: 'Settings' object has no attribute 'permissions_15'
2018-01-23 17:40:48,119 [Thread-71:140390544107264] [django.request:256] [base:handle_uncaught_exception] [ERROR]- Internal Server Error: /user/getUserInfo/
Traceback (most recent call last):
  File "/root/.virtualenvs/cms/lib/python3.5/site-packages/django/core/handlers/base.py", line 132, in get_response
    response = wrapped_callback(request, *callback_args, **callback_kwargs)
  File "/root/cms/cms/decorate.py", line 42, in inner
    return func(request, *args, **kwargs)
  File "/root/cms/cms/user/views.py", line 218, in getUserInfo
    user_count = len(user_infos)
TypeError: object of type 'NoneType' has no len()
2018-01-23 17:40:55,349 [Thread-79:140390544107264] [django.request:256] [base:handle_uncaught_exception] [ERROR]- Internal Server Error: /user/permissions/15
Traceback (most recent call last):
  File "/root/.virtualenvs/cms/lib/python3.5/site-packages/django/core/handlers/base.py", line 132, in get_response
    response = wrapped_callback(request, *callback_args, **callback_kwargs)
  File "/root/cms/cms/decorate.py", line 42, in inner
    return func(request, *args, **kwargs)
  File "/root/cms/cms/decorate.py", line 25, in inner
    return_value = func(request, *args, **kwargs)
  File "/root/cms/cms/user/views.py", line 200, in permissions
    return render(request, 'user/permissions.html', context=context)
  File "/root/.virtualenvs/cms/lib/python3.5/site-packages/django/shortcuts.py", line 67, in render
    template_name, context, request=request, using=using)
  File "/root/.virtualenvs/cms/lib/python3.5/site-packages/django/template/loader.py", line 98, in render_to_string
    template = get_template(template_name, using=using)
  File "/root/.virtualenvs/cms/lib/python3.5/site-packages/django/template/loader.py", line 35, in get_template
    return engine.get_template(template_name, dirs)
  File "/root/.virtualenvs/cms/lib/python3.5/site-packages/django/template/backends/django.py", line 30, in get_template
    return Template(self.engine.get_template(template_name, dirs))
  File "/root/.virtualenvs/cms/lib/python3.5/site-packages/django/template/engine.py", line 167, in get_template
    template, origin = self.find_template(template_name, dirs)
  File "/root/.virtualenvs/cms/lib/python3.5/site-packages/django/template/engine.py", line 141, in find_template
    source, display_name = loader(name, dirs)
  File "/root/.virtualenvs/cms/lib/python3.5/site-packages/django/template/loaders/base.py", line 13, in __call__
    return self.load_template(template_name, template_dirs)
  File "/root/.virtualenvs/cms/lib/python3.5/site-packages/django/template/loaders/base.py", line 23, in load_template
    template = Template(source, origin, template_name, self.engine)
  File "/root/.virtualenvs/cms/lib/python3.5/site-packages/django/template/base.py", line 190, in __init__
    self.nodelist = engine.compile_string(template_string, origin)
  File "/root/.virtualenvs/cms/lib/python3.5/site-packages/django/template/engine.py", line 261, in compile_string
    return parser.parse()
  File "/root/.virtualenvs/cms/lib/python3.5/site-packages/django/template/base.py", line 317, in parse
    filter_expression = self.compile_filter(token.contents)
  File "/root/.virtualenvs/cms/lib/python3.5/site-packages/django/template/base.py", line 423, in compile_filter
    return FilterExpression(token, self)
  File "/root/.virtualenvs/cms/lib/python3.5/site-packages/django/template/base.py", line 633, in __init__
    filter_func = parser.find_filter(filter_name)
  File "/root/.virtualenvs/cms/lib/python3.5/site-packages/django/template/base.py", line 429, in find_filter
    raise TemplateSyntaxError("Invalid filter: '%s'" % filter_name)
django.template.base.TemplateSyntaxError: Invalid filter: 'permiss'
2018-01-23 18:53:31,251 [Thread-869:140390334199552] [django.request:256] [base:handle_uncaught_exception] [ERROR]- Internal Server Error: /user/getUserInfo/
Traceback (most recent call last):
  File "/root/.virtualenvs/cms/lib/python3.5/site-packages/django/core/handlers/base.py", line 132, in get_response
    response = wrapped_callback(request, *callback_args, **callback_kwargs)
  File "/root/cms/cms/decorate.py", line 42, in inner
    return func(request, *args, **kwargs)
  File "/root/cms/cms/user/views.py", line 218, in getUserInfo
    user_count = len(user_infos)
TypeError: object of type 'NoneType' has no len()
2018-01-23 19:09:02,729 [Thread-1138:140390325282560] [django.request:256] [base:handle_uncaught_exception] [ERROR]- Internal Server Error: /user/getUserInfo/
Traceback (most recent call last):
  File "/root/.virtualenvs/cms/lib/python3.5/site-packages/django/core/handlers/base.py", line 132, in get_response
    response = wrapped_callback(request, *callback_args, **callback_kwargs)
  File "/root/cms/cms/decorate.py", line 42, in inner
    return func(request, *args, **kwargs)
  File "/root/cms/cms/user/views.py", line 218, in getUserInfo
    user_count = len(user_infos)
TypeError: object of type 'NoneType' has no len()
2018-01-23 19:38:46,907 [Thread-1164:140390325282560] [django.request:256] [base:handle_uncaught_exception] [ERROR]- Internal Server Error: /user/getUserInfo/
Traceback (most recent call last):
  File "/root/.virtualenvs/cms/lib/python3.5/site-packages/django/core/handlers/base.py", line 132, in get_response
    response = wrapped_callback(request, *callback_args, **callback_kwargs)
  File "/root/cms/cms/decorate.py", line 42, in inner
    return func(request, *args, **kwargs)
  File "/root/cms/cms/user/views.py", line 218, in getUserInfo
    user_count = len(user_infos)
TypeError: object of type 'NoneType' has no len()
2018-01-23 19:54:12,288 [Thread-1191:140390552499968] [django.request:256] [base:handle_uncaught_exception] [ERROR]- Internal Server Error: /user/getUserInfo/
Traceback (most recent call last):
  File "/root/.virtualenvs/cms/lib/python3.5/site-packages/django/core/handlers/base.py", line 132, in get_response
    response = wrapped_callback(request, *callback_args, **callback_kwargs)
  File "/root/cms/cms/decorate.py", line 42, in inner
    return func(request, *args, **kwargs)
  File "/root/cms/cms/user/views.py", line 218, in getUserInfo
    user_count = len(user_infos)
TypeError: object of type 'NoneType' has no len()
2018-01-23 20:10:16,831 [Thread-26:140179161720576] [django.request:256] [base:handle_uncaught_exception] [ERROR]- Internal Server Error: /user/listUser/
Traceback (most recent call last):
  File "/root/.virtualenvs/cms/lib/python3.5/site-packages/django/core/handlers/base.py", line 132, in get_response
    response = wrapped_callback(request, *callback_args, **callback_kwargs)
  File "/root/cms/cms/decorate.py", line 21, in inner
    permissions = settings.__getattr__(variable_name)
  File "/root/.virtualenvs/cms/lib/python3.5/site-packages/django/conf/__init__.py", line 49, in __getattr__
    return getattr(self._wrapped, name)
AttributeError: 'Settings' object has no attribute 'permissions_15'
2018-01-23 21:30:13,619 [Thread-1:140196310501120] [django.request:256] [base:handle_uncaught_exception] [ERROR]- Internal Server Error: /user/listUser/
Traceback (most recent call last):
  File "/root/.virtualenvs/cms/lib/python3.5/site-packages/django/core/urlresolvers.py", line 394, in urlconf_module
    return self._urlconf_module
AttributeError: 'RegexURLResolver' object has no attribute '_urlconf_module'

During handling of the above exception, another exception occurred:

Traceback (most recent call last):
  File "/root/.virtualenvs/cms/lib/python3.5/site-packages/django/core/handlers/base.py", line 119, in get_response
    resolver_match = resolver.resolve(request.path_info)
  File "/root/.virtualenvs/cms/lib/python3.5/site-packages/django/core/urlresolvers.py", line 366, in resolve
    for pattern in self.url_patterns:
  File "/root/.virtualenvs/cms/lib/python3.5/site-packages/django/core/urlresolvers.py", line 402, in url_patterns
    patterns = getattr(self.urlconf_module, "urlpatterns", self.urlconf_module)
  File "/root/.virtualenvs/cms/lib/python3.5/site-packages/django/core/urlresolvers.py", line 396, in urlconf_module
    self._urlconf_module = import_module(self.urlconf_name)
  File "/root/.virtualenvs/cms/lib/python3.5/importlib/__init__.py", line 126, in import_module
    return _bootstrap._gcd_import(name[level:], package, level)
  File "<frozen importlib._bootstrap>", line 986, in _gcd_import
  File "<frozen importlib._bootstrap>", line 969, in _find_and_load
  File "<frozen importlib._bootstrap>", line 958, in _find_and_load_unlocked
  File "<frozen importlib._bootstrap>", line 673, in _load_unlocked
  File "<frozen importlib._bootstrap_external>", line 665, in exec_module
  File "<frozen importlib._bootstrap>", line 222, in _call_with_frames_removed
  File "/root/cms/cms/cms/urls.py", line 22, in <module>
    url(r'^user/', include('user.urls', namespace='user')),
  File "/root/.virtualenvs/cms/lib/python3.5/site-packages/django/conf/urls/__init__.py", line 33, in include
    urlconf_module = import_module(urlconf_module)
  File "/root/.virtualenvs/cms/lib/python3.5/importlib/__init__.py", line 126, in import_module
    return _bootstrap._gcd_import(name[level:], package, level)
  File "<frozen importlib._bootstrap>", line 986, in _gcd_import
  File "<frozen importlib._bootstrap>", line 969, in _find_and_load
  File "<frozen importlib._bootstrap>", line 958, in _find_and_load_unlocked
  File "<frozen importlib._bootstrap>", line 673, in _load_unlocked
  File "<frozen importlib._bootstrap_external>", line 665, in exec_module
  File "<frozen importlib._bootstrap>", line 222, in _call_with_frames_removed
  File "/root/cms/cms/user/urls.py", line 18, in <module>
    from . import views
  File "/root/cms/cms/user/views.py", line 206
    @auth
    ^
IndentationError: expected an indented block
2018-01-23 21:30:20,862 [Thread-3:140196310501120] [django.request:256] [base:handle_uncaught_exception] [ERROR]- Internal Server Error: /user/logout/
Traceback (most recent call last):
  File "/root/.virtualenvs/cms/lib/python3.5/site-packages/django/core/urlresolvers.py", line 394, in urlconf_module
    return self._urlconf_module
AttributeError: 'RegexURLResolver' object has no attribute '_urlconf_module'

During handling of the above exception, another exception occurred:

Traceback (most recent call last):
  File "/root/.virtualenvs/cms/lib/python3.5/site-packages/django/core/handlers/base.py", line 119, in get_response
    resolver_match = resolver.resolve(request.path_info)
  File "/root/.virtualenvs/cms/lib/python3.5/site-packages/django/core/urlresolvers.py", line 366, in resolve
    for pattern in self.url_patterns:
  File "/root/.virtualenvs/cms/lib/python3.5/site-packages/django/core/urlresolvers.py", line 402, in url_patterns
    patterns = getattr(self.urlconf_module, "urlpatterns", self.urlconf_module)
  File "/root/.virtualenvs/cms/lib/python3.5/site-packages/django/core/urlresolvers.py", line 396, in urlconf_module
    self._urlconf_module = import_module(self.urlconf_name)
  File "/root/.virtualenvs/cms/lib/python3.5/importlib/__init__.py", line 126, in import_module
    return _bootstrap._gcd_import(name[level:], package, level)
  File "<frozen importlib._bootstrap>", line 986, in _gcd_import
  File "<frozen importlib._bootstrap>", line 969, in _find_and_load
  File "<frozen importlib._bootstrap>", line 958, in _find_and_load_unlocked
  File "<frozen importlib._bootstrap>", line 673, in _load_unlocked
  File "<frozen importlib._bootstrap_external>", line 665, in exec_module
  File "<frozen importlib._bootstrap>", line 222, in _call_with_frames_removed
  File "/root/cms/cms/cms/urls.py", line 22, in <module>
    url(r'^user/', include('user.urls', namespace='user')),
  File "/root/.virtualenvs/cms/lib/python3.5/site-packages/django/conf/urls/__init__.py", line 33, in include
    urlconf_module = import_module(urlconf_module)
  File "/root/.virtualenvs/cms/lib/python3.5/importlib/__init__.py", line 126, in import_module
    return _bootstrap._gcd_import(name[level:], package, level)
  File "<frozen importlib._bootstrap>", line 986, in _gcd_import
  File "<frozen importlib._bootstrap>", line 969, in _find_and_load
  File "<frozen importlib._bootstrap>", line 958, in _find_and_load_unlocked
  File "<frozen importlib._bootstrap>", line 673, in _load_unlocked
  File "<frozen importlib._bootstrap_external>", line 665, in exec_module
  File "<frozen importlib._bootstrap>", line 222, in _call_with_frames_removed
  File "/root/cms/cms/user/urls.py", line 18, in <module>
    from . import views
  File "/root/cms/cms/user/views.py", line 206
    @auth
    ^
IndentationError: expected an indented block
2018-01-23 22:09:15,333 [Thread-4:140196310501120] [django.request:256] [base:handle_uncaught_exception] [ERROR]- Internal Server Error: /user/login/
Traceback (most recent call last):
  File "/root/.virtualenvs/cms/lib/python3.5/site-packages/django/core/urlresolvers.py", line 394, in urlconf_module
    return self._urlconf_module
AttributeError: 'RegexURLResolver' object has no attribute '_urlconf_module'

During handling of the above exception, another exception occurred:

Traceback (most recent call last):
  File "/root/.virtualenvs/cms/lib/python3.5/site-packages/django/core/handlers/base.py", line 119, in get_response
    resolver_match = resolver.resolve(request.path_info)
  File "/root/.virtualenvs/cms/lib/python3.5/site-packages/django/core/urlresolvers.py", line 366, in resolve
    for pattern in self.url_patterns:
  File "/root/.virtualenvs/cms/lib/python3.5/site-packages/django/core/urlresolvers.py", line 402, in url_patterns
    patterns = getattr(self.urlconf_module, "urlpatterns", self.urlconf_module)
  File "/root/.virtualenvs/cms/lib/python3.5/site-packages/django/core/urlresolvers.py", line 396, in urlconf_module
    self._urlconf_module = import_module(self.urlconf_name)
  File "/root/.virtualenvs/cms/lib/python3.5/importlib/__init__.py", line 126, in import_module
    return _bootstrap._gcd_import(name[level:], package, level)
  File "<frozen importlib._bootstrap>", line 986, in _gcd_import
  File "<frozen importlib._bootstrap>", line 969, in _find_and_load
  File "<frozen importlib._bootstrap>", line 958, in _find_and_load_unlocked
  File "<frozen importlib._bootstrap>", line 673, in _load_unlocked
  File "<frozen importlib._bootstrap_external>", line 665, in exec_module
  File "<frozen importlib._bootstrap>", line 222, in _call_with_frames_removed
  File "/root/cms/cms/cms/urls.py", line 27, in <module>
    url(r'^device/', include('device.urls', namespace='device')),
  File "/root/.virtualenvs/cms/lib/python3.5/site-packages/django/conf/urls/__init__.py", line 33, in include
    urlconf_module = import_module(urlconf_module)
  File "/root/.virtualenvs/cms/lib/python3.5/importlib/__init__.py", line 126, in import_module
    return _bootstrap._gcd_import(name[level:], package, level)
  File "<frozen importlib._bootstrap>", line 986, in _gcd_import
  File "<frozen importlib._bootstrap>", line 969, in _find_and_load
  File "<frozen importlib._bootstrap>", line 958, in _find_and_load_unlocked
  File "<frozen importlib._bootstrap>", line 673, in _load_unlocked
  File "<frozen importlib._bootstrap_external>", line 665, in exec_module
  File "<frozen importlib._bootstrap>", line 222, in _call_with_frames_removed
  File "/root/cms/cms/device/urls.py", line 18, in <module>
    from . import views
  File "/root/cms/cms/device/views.py", line 11, in <module>
    @auth
NameError: name 'auth' is not defined
2018-01-23 22:27:51,760 [Thread-26:139888418612992] [django.request:256] [base:handle_uncaught_exception] [ERROR]- Internal Server Error: /device/main/
Traceback (most recent call last):
  File "/root/.virtualenvs/cms/lib/python3.5/site-packages/django/core/urlresolvers.py", line 565, in reverse
    extra, resolver = resolver.namespace_dict[ns]
KeyError: 'cms.user'

During handling of the above exception, another exception occurred:

Traceback (most recent call last):
  File "/root/.virtualenvs/cms/lib/python3.5/site-packages/django/template/defaulttags.py", line 501, in render
    current_app=current_app)
  File "/root/.virtualenvs/cms/lib/python3.5/site-packages/django/core/urlresolvers.py", line 575, in reverse
    key)
django.core.urlresolvers.NoReverseMatch: 'cms.user' is not a registered namespace

During handling of the above exception, another exception occurred:

Traceback (most recent call last):
  File "/root/.virtualenvs/cms/lib/python3.5/site-packages/django/core/handlers/base.py", line 132, in get_response
    response = wrapped_callback(request, *callback_args, **callback_kwargs)
  File "/root/cms/cms/device/views.py", line 14, in main
    return render(request, 'device/main.html')
  File "/root/.virtualenvs/cms/lib/python3.5/site-packages/django/shortcuts.py", line 67, in render
    template_name, context, request=request, using=using)
  File "/root/.virtualenvs/cms/lib/python3.5/site-packages/django/template/loader.py", line 99, in render_to_string
    return template.render(context, request)
  File "/root/.virtualenvs/cms/lib/python3.5/site-packages/django/template/backends/django.py", line 74, in render
    return self.template.render(context)
  File "/root/.virtualenvs/cms/lib/python3.5/site-packages/django/template/base.py", line 209, in render
    return self._render(context)
  File "/root/.virtualenvs/cms/lib/python3.5/site-packages/django/template/base.py", line 201, in _render
    return self.nodelist.render(context)
  File "/root/.virtualenvs/cms/lib/python3.5/site-packages/django/template/base.py", line 903, in render
    bit = self.render_node(node, context)
  File "/root/.virtualenvs/cms/lib/python3.5/site-packages/django/template/debug.py", line 79, in render_node
    return node.render(context)
  File "/root/.virtualenvs/cms/lib/python3.5/site-packages/django/template/defaulttags.py", line 507, in render
    six.reraise(*exc_info)
  File "/root/.virtualenvs/cms/lib/python3.5/site-packages/django/utils/six.py", line 659, in reraise
    raise value
  File "/root/.virtualenvs/cms/lib/python3.5/site-packages/django/template/defaulttags.py", line 493, in render
    url = reverse(view_name, args=args, kwargs=kwargs, current_app=current_app)
  File "/root/.virtualenvs/cms/lib/python3.5/site-packages/django/core/urlresolvers.py", line 579, in reverse
    return force_text(iri_to_uri(resolver._reverse_with_prefix(view, prefix, *args, **kwargs)))
  File "/root/.virtualenvs/cms/lib/python3.5/site-packages/django/core/urlresolvers.py", line 496, in _reverse_with_prefix
    (lookup_view_s, args, kwargs, len(patterns), patterns))
django.core.urlresolvers.NoReverseMatch: Reverse for 'getDeviceData' with arguments '()' and keyword arguments '{}' not found. 0 pattern(s) tried: []
2018-01-23 22:28:22,555 [Thread-51:139888510551808] [django.request:256] [base:handle_uncaught_exception] [ERROR]- Internal Server Error: /device/main/
Traceback (most recent call last):
  File "/root/.virtualenvs/cms/lib/python3.5/site-packages/django/core/urlresolvers.py", line 565, in reverse
    extra, resolver = resolver.namespace_dict[ns]
KeyError: 'cms.device'

During handling of the above exception, another exception occurred:

Traceback (most recent call last):
  File "/root/.virtualenvs/cms/lib/python3.5/site-packages/django/template/defaulttags.py", line 501, in render
    current_app=current_app)
  File "/root/.virtualenvs/cms/lib/python3.5/site-packages/django/core/urlresolvers.py", line 575, in reverse
    key)
django.core.urlresolvers.NoReverseMatch: 'cms.device' is not a registered namespace

During handling of the above exception, another exception occurred:

Traceback (most recent call last):
  File "/root/.virtualenvs/cms/lib/python3.5/site-packages/django/core/handlers/base.py", line 132, in get_response
    response = wrapped_callback(request, *callback_args, **callback_kwargs)
  File "/root/cms/cms/device/views.py", line 14, in main
    return render(request, 'device/main.html')
  File "/root/.virtualenvs/cms/lib/python3.5/site-packages/django/shortcuts.py", line 67, in render
    template_name, context, request=request, using=using)
  File "/root/.virtualenvs/cms/lib/python3.5/site-packages/django/template/loader.py", line 99, in render_to_string
    return template.render(context, request)
  File "/root/.virtualenvs/cms/lib/python3.5/site-packages/django/template/backends/django.py", line 74, in render
    return self.template.render(context)
  File "/root/.virtualenvs/cms/lib/python3.5/site-packages/django/template/base.py", line 209, in render
    return self._render(context)
  File "/root/.virtualenvs/cms/lib/python3.5/site-packages/django/template/base.py", line 201, in _render
    return self.nodelist.render(context)
  File "/root/.virtualenvs/cms/lib/python3.5/site-packages/django/template/base.py", line 903, in render
    bit = self.render_node(node, context)
  File "/root/.virtualenvs/cms/lib/python3.5/site-packages/django/template/debug.py", line 79, in render_node
    return node.render(context)
  File "/root/.virtualenvs/cms/lib/python3.5/site-packages/django/template/defaulttags.py", line 507, in render
    six.reraise(*exc_info)
  File "/root/.virtualenvs/cms/lib/python3.5/site-packages/django/utils/six.py", line 659, in reraise
    raise value
  File "/root/.virtualenvs/cms/lib/python3.5/site-packages/django/template/defaulttags.py", line 493, in render
    url = reverse(view_name, args=args, kwargs=kwargs, current_app=current_app)
  File "/root/.virtualenvs/cms/lib/python3.5/site-packages/django/core/urlresolvers.py", line 579, in reverse
    return force_text(iri_to_uri(resolver._reverse_with_prefix(view, prefix, *args, **kwargs)))
  File "/root/.virtualenvs/cms/lib/python3.5/site-packages/django/core/urlresolvers.py", line 496, in _reverse_with_prefix
    (lookup_view_s, args, kwargs, len(patterns), patterns))
django.core.urlresolvers.NoReverseMatch: Reverse for 'getDeviceData' with arguments '()' and keyword arguments '{}' not found. 0 pattern(s) tried: []
2018-01-23 22:28:28,932 [Thread-57:139888510551808] [django.request:256] [base:handle_uncaught_exception] [ERROR]- Internal Server Error: /device/main/
Traceback (most recent call last):
  File "/root/.virtualenvs/cms/lib/python3.5/site-packages/django/core/urlresolvers.py", line 565, in reverse
    extra, resolver = resolver.namespace_dict[ns]
KeyError: 'cms.device'

During handling of the above exception, another exception occurred:

Traceback (most recent call last):
  File "/root/.virtualenvs/cms/lib/python3.5/site-packages/django/template/defaulttags.py", line 501, in render
    current_app=current_app)
  File "/root/.virtualenvs/cms/lib/python3.5/site-packages/django/core/urlresolvers.py", line 575, in reverse
    key)
django.core.urlresolvers.NoReverseMatch: 'cms.device' is not a registered namespace

During handling of the above exception, another exception occurred:

Traceback (most recent call last):
  File "/root/.virtualenvs/cms/lib/python3.5/site-packages/django/core/handlers/base.py", line 132, in get_response
    response = wrapped_callback(request, *callback_args, **callback_kwargs)
  File "/root/cms/cms/device/views.py", line 14, in main
    return render(request, 'device/main.html')
  File "/root/.virtualenvs/cms/lib/python3.5/site-packages/django/shortcuts.py", line 67, in render
    template_name, context, request=request, using=using)
  File "/root/.virtualenvs/cms/lib/python3.5/site-packages/django/template/loader.py", line 99, in render_to_string
    return template.render(context, request)
  File "/root/.virtualenvs/cms/lib/python3.5/site-packages/django/template/backends/django.py", line 74, in render
    return self.template.render(context)
  File "/root/.virtualenvs/cms/lib/python3.5/site-packages/django/template/base.py", line 209, in render
    return self._render(context)
  File "/root/.virtualenvs/cms/lib/python3.5/site-packages/django/template/base.py", line 201, in _render
    return self.nodelist.render(context)
  File "/root/.virtualenvs/cms/lib/python3.5/site-packages/django/template/base.py", line 903, in render
    bit = self.render_node(node, context)
  File "/root/.virtualenvs/cms/lib/python3.5/site-packages/django/template/debug.py", line 79, in render_node
    return node.render(context)
  File "/root/.virtualenvs/cms/lib/python3.5/site-packages/django/template/defaulttags.py", line 507, in render
    six.reraise(*exc_info)
  File "/root/.virtualenvs/cms/lib/python3.5/site-packages/django/utils/six.py", line 659, in reraise
    raise value
  File "/root/.virtualenvs/cms/lib/python3.5/site-packages/django/template/defaulttags.py", line 493, in render
    url = reverse(view_name, args=args, kwargs=kwargs, current_app=current_app)
  File "/root/.virtualenvs/cms/lib/python3.5/site-packages/django/core/urlresolvers.py", line 579, in reverse
    return force_text(iri_to_uri(resolver._reverse_with_prefix(view, prefix, *args, **kwargs)))
  File "/root/.virtualenvs/cms/lib/python3.5/site-packages/django/core/urlresolvers.py", line 496, in _reverse_with_prefix
    (lookup_view_s, args, kwargs, len(patterns), patterns))
django.core.urlresolvers.NoReverseMatch: Reverse for 'getDeviceData' with arguments '()' and keyword arguments '{}' not found. 0 pattern(s) tried: []
2018-01-23 22:29:33,667 [Thread-27:140300366771968] [django.request:256] [base:handle_uncaught_exception] [ERROR]- Internal Server Error: /device/getDeviceData/
Traceback (most recent call last):
  File "/root/.virtualenvs/cms/lib/python3.5/site-packages/django/core/handlers/base.py", line 132, in get_response
    response = wrapped_callback(request, *callback_args, **callback_kwargs)
  File "/root/cms/cms/decorate.py", line 42, in inner
    return func(request, *args, **kwargs)
  File "/root/cms/cms/device/views.py", line 35, in getDeviceData
    user_count = len(user_infos)
TypeError: object of type 'NoneType' has no len()
2018-01-23 23:29:45,639 [Thread-1:139929784547072] [django.request:256] [base:handle_uncaught_exception] [ERROR]- Internal Server Error: /device/UpDataDevState/
Traceback (most recent call last):
  File "/root/.virtualenvs/cms/lib/python3.5/site-packages/django/core/handlers/base.py", line 151, in get_response
    % (callback.__module__, view_name))
ValueError: The view device.views.UpDataDevState didn't return an HttpResponse object. It returned None instead.
2018-01-23 23:30:06,474 [Thread-8:139929784547072] [django.request:256] [base:handle_uncaught_exception] [ERROR]- Internal Server Error: /device/UpDataDevState/
Traceback (most recent call last):
  File "/root/.virtualenvs/cms/lib/python3.5/site-packages/django/core/handlers/base.py", line 151, in get_response
    % (callback.__module__, view_name))
ValueError: The view device.views.UpDataDevState didn't return an HttpResponse object. It returned None instead.
2018-01-23 23:41:20,051 [Thread-1:140457095567104] [django.request:256] [base:handle_uncaught_exception] [ERROR]- Internal Server Error: /user/listUser/
Traceback (most recent call last):
  File "/root/.virtualenvs/cms/lib/python3.5/site-packages/django/core/handlers/base.py", line 132, in get_response
    response = wrapped_callback(request, *callback_args, **callback_kwargs)
  File "/root/cms/cms/decorate.py", line 21, in inner
    permissions = settings.__getattr__(variable_name)
  File "/root/.virtualenvs/cms/lib/python3.5/site-packages/django/conf/__init__.py", line 49, in __getattr__
    return getattr(self._wrapped, name)
AttributeError: 'Settings' object has no attribute 'permissions_15'
